package meowmel.pollution.common.machine.multiblock.botania;

import com.gregtechceu.gtceu.api.machine.MultiblockMachineDefinition;
import com.gregtechceu.gtceu.api.machine.multiblock.PartAbility;
import com.gregtechceu.gtceu.api.pattern.BlockPattern;
import com.gregtechceu.gtceu.api.pattern.FactoryBlockPattern;
import com.gregtechceu.gtceu.api.pattern.Predicates;
import com.gregtechceu.gtceu.common.data.GTBlocks;
import meowmel.pollution.common.block.PollutionMagicBlocks;
import vazkii.botania.common.block.BotaniaBlocks;

/**
 * Structure of the Life Activation Garden, converted 1:1 from the 1.12.2 aisles
 * of {@code MetaTileEntityMultiDanDeLifeOn} (63 x 10 x 63).
 *
 * <p>Deviations:</p>
 * <ul>
 *   <li>The GTQT tiered coil casings map to GregTech heating coils.</li>
 *   <li>Upstream substituted the GTQT biological PCB casing and the "leaves"
 *       and "alt grass" decorations with mana plates; the port keeps those
 *       substitutions (fusion casing MK3 and {@code MANA_3}).</li>
 *   <li>The upstream preview suppression ({@code getMatchingShapes} returning
 *       empty) is expressed with {@code renderMultiblockXEIPreview(false)} in
 *       the machine registration, because a 39,690-position JEI preview stalls
 *       client startup.</li>
 * </ul>
 */
final class MultiDanDeLifeOnPatterns {

    static BlockPattern create(MultiblockMachineDefinition definition) {
        return FactoryBlockPattern.start()
                .aisle("AAAAAAAAAAAAAAAAAAAAAAAAAAAAAAAAAAAAAAAAAAAAAAAAAAAAAAAAAAAAAAA", "BBBBBBBBBBBBBBBBBBBBBBBBBBBBBBBBBBBBBBBBBBBBBBBBBBBBBBBBBBBBBBB", "AAAAAAAAAAAAAAAAAAAAAAAAAAAAAAGGGAAAAAAAAAAAAAAAAAAAAAAAAAAAAAA", "                                                               ", "                                                               ", "                                                               ", "                                                               ", "                                                               ", "                                                               ", "                                                               " )
                .aisle("AAAAAAAAAAAAAAAAAAAAAAAAAAAAAAAAAAAAAAAAAAAAAAAAAAAAAAAAAAAAAAA", "BCCCCCCCCCCCCCCCCCCCCCCCCCCCCCCCCCCCCCCCCCCCCCCCCCCCCCCCCCCCCCB", "ADDDDDDDDDDDDDDDDDDDDDDDDDDDDDDDDDDDDDDDDDDDDDDDDDDDDDDDDDDDDDA", " QQQQQQQQQQQQQQQQQQQQQQQQQQQI     IQQQQQQQQQQQQQQQQQQQQQQQQQQQ ", " Q                          Q     Q                          Q ", " M                          Q     Q                          M ", " N                          Q     Q                          N ", "                            Q     Q                            ", "                            QQ   QQ                            ", "                             QQQQQ                             " )
                .aisle("AAAAAAAAAAAAAAAAAAAAAAAAAAAAAAAAAAAAAAAAAAAAAAAAAAAAAAAAAAAAAAA", "BCOOOOOOOOOOOOOOOOOOOOOOOOOOOOOOOOOOOOOOOOOOOOOOOOOOOOOOOOOOOCB", "ADPPPPPPPPPPPPPPPPPPPPPPPPPPPPPPPPPPPPPPPPPPPPPPPPPPPPPPPPPPPDA", " Q                                                           Q ", "                                                               ", "                                                               ", "                                                               ", "                                                               ", "                            Q     Q                            ", "                            Q     Q                            " )
                .aisle("AAAAAAAAAAAAAAAAAAAAAAAAAAAAAAAAAAAAAAAAAAAAAAAAAAAAAAAAAAAAAAA", "BCORRRRRRRRRRRRRRRRRRRRRRRRRRRRRRRRRRRRRRRRRRRRRRRRRRRRRRRRROCB", "ADPPPPPPPPPPPPPPPPPPPPPPPPPPPPPPPPPPPPPPPPPPPPPPPPPPPPPPPPPPPDA", " Q                                                           Q ", "                                                               ", "                                                               ", "                                                               ", "                                                               ", "                                                               ", "                            Q     Q                            " )
                .aisle("AAAAAAAAAAAAAAAAAAAAAAAAAAAAAAAAAAAAAAAAAAAAAAAAAAAAAAAAAAAAAAA", "BCORTTTTTTTTTTTTTTTTTTTTTTTTTTTTTTTTTTTTTTTTTTTTTTTTTTTTTTTROCB", "ADPPPPPPPPPPPPPPPPPPPPPPPPPPPPPPPPPPPPPPPPPPPPPPPPPPPPPPPPPPPDA", " Q                                                           Q ", "                                                               ", "                                                               ", "                                                               ", "                                                               ", "                                                               ", "                            Q     Q                            " )
                .aisle("AAAAAAAAAAAAAAAAAAAAAAAAAAAAAAAAAAAAAAAAAAAAAAAAAAAAAAAAAAAAAAA", "BCORTVVVVVVVVVVVVVVVVVVVVVVVVVVVVVVVVVVVVVVVVVVVVVVVVVVVVVTROCB", "ADPPPPPPPPPPPPPPPPPPPPPPPPPPPPPPPPPPPPPPPPPPPPPPPPPPPPPPPPPPPDA", " Q                                                           Q ", "                                                               ", "                                                               ", "                                                               ", "                                                               ", "                            Q     Q                            ", "                            Q     Q                            " )
                .aisle("AAAAAAAAAAAAAAAAAAAAAAAAAAAAAAAAAAAAAAAAAAAAAAAAAAAAAAAAAAAAAAA", "BCORTVWWWWWWWWWWWWWWWWWWWWWWWWWWWWWWWWWWWWWWWWWWWWWWWWWWWVTROCB", "ADPPPPDDDDDDDDDDDDDDDDDDDDDDDDDDDDDDDDDDDDDDDDDDDDDDDDDDDPPPPDA", " Q    QQQQQQQQQQQQQQQQQQQQQQI     IQQQQQQQQQQQQQQQQQQQQQQ    Q ", "      M                     Q     Q                     M      ", "      N                     Q     Q                     N      ", "                            Q     Q                            ", "                            Q     Q                            ", "                            QQ   QQ                            ", "                             QQQQQ                             " )
                .aisle("AAAAAAAAAAAAAAAAAAAAAAAAAAAAAAAAAAAAAAAAAAAAAAAAAAAAAAAAAAAAAAA", "BCORTVWXXXXXXXXXXXXXXXXXXXXXXXXXXXXXXXXXXXXXXXXXXXXXXXXXWVTROCB", "ADPPPPDBBBBBBBBBBBBBBBBBBBBBBBBBBBBBBBBBBBBBBBBBBBBBBBBBDPPPPDA", " Q    Q                                                 Q    Q ", "                                                               ", "                                                               ", "                                                               ", "                                                               ", "                                                               ", "                                                               " )
                .aisle("AAAAAAAAAAAAAAAAAAAAAAAAAAAAAAAAAAAAAAAAAAAAAAAAAAAAAAAAAAAAAAA", "BCORTVWXYYYYYYYYYYYYYYYYYYYYYYYYYYYYYYYYYYYYYYYYYYYYYYYXWVTROCB", "ADPPPPDB                                               BDPPPPDA", " Q    Q                                                 Q    Q ", "                                                               ", "                                                               ", "                                                               ", "                                                               ", "                                                               ", "                                                               " )
                .aisle("AAAAAAAAAAAAAAAAAAAAAAAAAAAAAAAAAAAAAAAAAAAAAAAAAAAAAAAAAAAAAAA", "BCORTVWXYZZZZZZZZZZZZZZZZZZZZZZZZZZZZZZZZZZZZZZZZZZZZZYXWVTROCB", "ADPPPPDB                                               BDPPPPDA", " Q    Q                                                 Q    Q ", "                                                               ", "                                                               ", "                                                               ", "                                                               ", "                                                               ", "                                                               " )
                .aisle("AAAAAAAAAAAAAAAAAAAAAAAAAAAAAAAAAAAAAAAAAAAAAAAAAAAAAAAAAAAAAAA", "BCORTVWXYZZZZZZZZZZZZZZZZZZZZZZZZZZZZZZZZZZZZZZZZZZZZZYXWVTROCB", "ADPPPPDB                                               BDPPPPDA", " Q    Q                                                 Q    Q ", "                                                               ", "                                                               ", "                                                               ", "                                                               ", "                                                               ", "                                                               " )
                .aisle("AAAAAAAAAAAAAAAAAAAAAAAAAAAAAAAAAAAAAAAAAAAAAAAAAAAAAAAAAAAAAAA", "BCORTVWXYZZZZZZZZZZZZZZZZZZZZZZZZZZZZZZZZZZZZZZZZZZZZZYXWVTROCB", "ADPPPPDB                                               BDPPPPDA", " Q    Q                                                 Q    Q ", "                                                               ", "                                                               ", "                                                               ", "                                                               ", "                                                               ", "                                                               " )
                .aisle("AAAAAAAAAAAAAAAAAAAAAAAAAAAAAAAAAAAAAAAAAAAAAAAAAAAAAAAAAAAAAAA", "BCORTVWXYZZZZZZZZZZZZZZZZZZZZZZZZZZZZZZZZZZZZZZZZZZZZZYXWVTROCB", "ADPPPPDB                                               BDPPPPDA", " Q    Q                                                 Q    Q ", "                                                               ", "                                                               ", "                                                               ", "                                                               ", "                                                               ", "                                                               " )
                .aisle("AAAAAAAAAAAAAAAAAAAAAAAAAAAAAAAAAAAAAAAAAAAAAAAAAAAAAAAAAAAAAAA", "BCORTVWXYZZZZOOOOOOOOOOOOOOOOOOOOOOOOOOOOOOOOOOOOOZZZZYXWVTROCB", "ADPPPPDB     GGGGGGGGGGGGGGGGGGGGGGGGGGGGGGGGGGGGG     BDPPPPDA", " Q    Q      F                                   F      Q    Q ", "                                                               ", "                                                               ", "                                                               ", "                                                               ", "                                                               ", "                                                               " )
                .aisle("AAAAAAAAAAAAAAAAAAAAAAAAAAAAAAAAAAAAAAAAAAAAAAAAAAAAAAAAAAAAAAA", "BCORTVWXYZZZZOYYYYYYYYYYYYYYYYYYYYYYYYYYYYYYYYYYYOZZZZYXWVTROCB", "ADPPPPDB     G                                   G     BDPPPPDA", " Q    Q                                                 Q    Q ", "                                                               ", "                                                               ", "                                                               ", "                                                               ", "                                                               ", "                                                               " )
                .aisle("AAAAAAAAAAAAAAAAAAAAAAAAAAAAAAAAAAAAAAAAAAAAAAAAAAAAAAAAAAAAAAA", "BCORTVWXYZZZZOYCCCCCCCCCCCCCCCCCCCCCCCCCCCCCCCCCYOZZZZYXWVTROCB", "ADPPPPDB     G BBBBBBBBBBBBBBBBBBBBBBBBBBBBBBBBB G     BDPPPPDA", " Q    Q                                                 Q    Q ", "                                                               ", "                                                               ", "                                                               ", "                                                               ", "                                                               ", "                                                               " )
                .aisle("AAAAAAAAAAAAAAAAAAAAAAAAAAAAAAAAAAAAAAAAAAAAAAAAAAAAAAAAAAAAAAA", "BCORTVWXYZZZZOYCGHGHGHGHGHGHGHGHGHGHGHGHGHGHGHGCYOZZZZYXWVTROCB", "ADPPPPDB     G BZPZPZPZPZPZPZPZPZPZPZPZPZPZPZPZB G     BDPPPPDA", " Q    Q                                                 Q    Q ", "                                                               ", "                                                               ", "                                                               ", "                                                               ", "                                                               ", "                                                               " )
                .aisle("AAAAAAAAAAAAAAAAAAAAAAAAAAAAAAAAAAAAAAAAAAAAAAAAAAAAAAAAAAAAAAA", "BCORTVWXYZZZZOYCHGHGHGHGHGHGHGHGHGHGHGHGHGHGHGHCYOZZZZYXWVTROCB", "ADPPPPDB     G BPZPZPZPZPZPZPZPZPZPZPZPZPZPZPZPB G     BDPPPPDA", " Q    Q                                                 Q    Q ", "                                                               ", "                                                               ", "                                                               ", "                                                               ", "                                                               ", "                                                               " )
                .aisle("AAAAAAAAAAAAAAAAAAAAAAAAAAAAAAAAAAAAAAAAAAAAAAAAAAAAAAAAAAAAAAA", "BCORTVWXYZZZZOYCGHGHGHGHGHGHGHGHGHGHGHGHGHGHGHGCYOZZZZYXWVTROCB", "ADPPPPDB     G BZPZPZPZPZPZPZPZPZPZPZPZPZPZPZPZB G     BDPPPPDA", " Q    Q                                                 Q    Q ", "                                                               ", "                                                               ", "                                                               ", "                                                               ", "                                                               ", "                                                               " )
                .aisle("AAAAAAAAAAAAAAAAAAAAAAAAAAAAAAAAAAAAAAAAAAAAAAAAAAAAAAAAAAAAAAA", "BCORTVWXYZZZZOYCHGHGHGHGHGHGHGHGHGHGHGHGHGHGHGHCYOZZZZYXWVTROCB", "ADPPPPDB     G BPZPZPZPZPZPZPZPZPZPZPZPZPZPZPZPB G     BDPPPPDA", " Q    Q                                                 Q    Q ", "                                                               ", "                                                               ", "                                                               ", "                                                               ", "                                                               ", "                                                               " )
                .aisle("AAAAAAAAAAAAAAAAAAAAAAAAAAAAAAAAAAAAAAAAAAAAAAAAAAAAAAAAAAAAAAA", "BCORTVWXYZZZZOYCGHGHGHGHGHGHGHGHGHGHGHGHGHGHGHGCYOZZZZYXWVTROCB", "ADPPPPDB     G BZPZPZPZPZPZPZPZPZPZPZPZPZPZPZPZB G     BDPPPPDA", " Q    Q                                                 Q    Q ", "                                                               ", "                                                               ", "                                                               ", "                                                               ", "                                                               ", "                                                               " )
                .aisle("AAAAAAAAAAAAAAAAAAAAAAAAAAAAAAAAAAAAAAAAAAAAAAAAAAAAAAAAAAAAAAA", "BCORTVWXYZZZZOYCHGHGHGHGHGHGHGHGHGHGHGHGHGHGHGHCYOZZZZYXWVTROCB", "ADPPPPDB     G BPZPZPZPZPZPZPZPZPZPZPZPZPZPZPZPB G     BDPPPPDA", " Q    Q                                                 Q    Q ", "                                                               ", "                                                               ", "                                                               ", "                                                               ", "                                                               ", "                                                               " )
                .aisle("AAAAAAAAAAAAAAAAAAAAAAAAAAAAAAAAAAAAAAAAAAAAAAAAAAAAAAAAAAAAAAA", "BCORTVWXYZZZZOYCGHGHGHGHGHGHGHGHGHGHGHGHGHGHGHGCYOZZZZYXWVTROCB", "ADPPPPDB     G BZPZPZPZPZPZPZPZPZPZPZPZPZPZPZPZB G     BDPPPPDA", " Q    Q                                                 Q    Q ", "                                                               ", "                                                               ", "                                                               ", "                                                               ", "                                                               ", "                                                               " )
                .aisle("AAAAAAAAAAAAAAAAAAAAAAAAAAAAAAAAAAAAAAAAAAAAAAAAAAAAAAAAAAAAAAA", "BCORTVWXYZZZZOYCHGHGHGHGHGHGHGHGHGHGHGHGHGHGHGHCYOZZZZYXWVTROCB", "ADPPPPDB     G BPZPZPZPZPZPZPZPZPZPZPZPZPZPZPZPB G     BDPPPPDA", " Q    Q                                                 Q    Q ", "                                                               ", "                                                               ", "                                                               ", "                                                               ", "                                                               ", "                                                               " )
                .aisle("AAAAAAAAAAAAAAAAAAAAAAAAAAAAAAAAAAAAAAAAAAAAAAAAAAAAAAAAAAAAAAA", "BCORTVWXYZZZZOYCGHGHGHGHGHGHGHGHGHGHGHGHGHGHGHGCYOZZZZYXWVTROCB", "ADPPPPDB     G BZPZPZPZPZPZPZPZPZPZPZPZPZPZPZPZB G     BDPPPPDA", " Q    Q                                                 Q    Q ", "                                                               ", "                                                               ", "                                                               ", "                                                               ", "                                                               ", "                                                               " )
                .aisle("AAAAAAAAAAAAAAAAAAAAAAAAAAAAAAAAAAAAAAAAAAAAAAAAAAAAAAAAAAAAAAA", "BCORTVWXYZZZZOYCHGHGHGHGHGHGHGHGHGHGHGHGHGHGHGHCYOZZZZYXWVTROCB", "ADPPPPDB     G BPZPZPZPZPZPZPZPZPZPZPZPZPZPZPZPB G     BDPPPPDA", " Q    Q                                                 Q    Q ", "                                                               ", "                                                               ", "                                                               ", "                                                               ", "                                                               ", "                                                               " )
                .aisle("AAAAAAAAAAAAAAAAAAAAAAAAAAAAAAAAAAAAAAAAAAAAAAAAAAAAAAAAAAAAAAA", "BCORTVWXYZZZZOYCGHGHGHGHGHGHGHGHGHGHGHGHGHGHGHGCYOZZZZYXWVTROCB", "ADPPPPDB     G BZPZPZPZPZPZPZPZPZPZPZPZPZPZPZPZB G     BDPPPPDA", " Q    Q                                                 Q    Q ", "                                                               ", "                                                               ", "                                                               ", "                                                               ", "                                                               ", "                                                               " )
                .aisle("AAAAAAAAAAAAAAAAAAAAAAAAAAAAAAAAAAAAAAAAAAAAAAAAAAAAAAAAAAAAAAA", "BCORTVWXYZZZZOYCHGHGHGHGHGHGHGHGHGHGHGHGHGHGHGHCYOZZZZYXWVTROCB", "ADPPPPDB     G BPZPZPZPZPZPZPZPZPZPZPZPZPZPZPZPB G     BDPPPPDA", " Q    Q                                                 Q    Q ", "                                                               ", "                                                               ", "                                                               ", "                                                               ", "                                                               ", "                                                               " )
                .aisle("AAAAAAAAAAAAAAAAAAAAAAAAAAAAAAAAAAAAAAAAAAAAAAAAAAAAAAAAAAAAAAA", "BCORTVWXYZZZZOYCGHGHGHGHGHGHGHGHGHGHGHGHGHGHGHGCYOZZZZYXWVTROCB", "ADPPPPDB     G BZPZPZPZPZPZPZPZPZPZPZPZPZPZPZPZB G     BDPPPPDA", " I    I                                                 I    I ", " Q    Q                                                 Q    Q ", " Q    Q                                                 Q    Q ", " Q    Q                                                 Q    Q ", " Q    Q                                                 Q    Q ", " QQ  QQ                                                 QQ  QQ ", "  QQQQ                                                   QQQQ  " )
                .aisle("AAAAAAAAAAAAAAAAAAAAAAAAAAAAAAAAAAAAAAAAAAAAAAAAAAAAAAAAAAAAAAA", "BCORTVWXYZZZZOYCHGHGHGHGHGHGHGHGHGHGHGHGHGHGHGHCYOZZZZYXWVTROCB", "ADPPPPDB     G BPZPZPZPZPZPZPZPZPZPZPZPZPZPZPZPB G     BDPPPPDA", "                                                               ", "                                                               ", "                                                               ", "                                                               ", "                                                               ", " Q    Q                                                 Q    Q ", " Q    Q                                                 Q    Q " )
                .aisle("AAAAAAAAAAAAAAAAAAAAAAAAAAAAAAAAAAAAAAAAAAAAAAAAAAAAAAAAAAAAAAA", "BCORTVWXYZZZZOYCGHGHGHGHGHGHGHGHGHGHGHGHGHGHGHGCYOZZZZYXWVTROCB", "GDPPPPDB     G BZPZPZPZPZPZPZPZPZPZPZPZPZPZPZPZB G     BDPPPPDG", "                                                               ", "                                                               ", "                                                               ", "                                                               ", "                                                               ", "                                                               ", " Q    Q                                                 Q    Q " )
                .aisle("AAAAAAAAAAAAAAAAAAAAAAAAAAAAAAAAAAAAAAAAAAAAAAAAAAAAAAAAAAAAAAA", "BCORTVWXYZZZZOYCHGHGHGHGHGHGHGHGHGHGHGHGHGHGHGHCYOZZZZYXWVTROCB", "GDPPPPDB     G BPZPZPZPZPZPZPZPZPZPZPZPZPZPZPZPB G     BDPPPPDG", "                                                               ", "                                                               ", "                                                               ", "                                                               ", "                                                               ", "                                                               ", " Q    Q                                                 Q    Q " )
                .aisle("AAAAAAAAAAAAAAAAAAAAAAAAAAAAAAAAAAAAAAAAAAAAAAAAAAAAAAAAAAAAAAA", "BCORTVWXYZZZZOYCGHGHGHGHGHGHGHGHGHGHGHGHGHGHGHGCYOZZZZYXWVTROCB", "GDPPPPDB     G BZPZPZPZPZPZPZPZPZPZPZPZPZPZPZPZB G     BDPPPPDG", "                                                               ", "                                                               ", "                                                               ", "                                                               ", "                                                               ", "                                                               ", " Q    Q                                                 Q    Q " )
                .aisle("AAAAAAAAAAAAAAAAAAAAAAAAAAAAAAAAAAAAAAAAAAAAAAAAAAAAAAAAAAAAAAA", "BCORTVWXYZZZZOYCHGHGHGHGHGHGHGHGHGHGHGHGHGHGHGHCYOZZZZYXWVTROCB", "ADPPPPDB     G BPZPZPZPZPZPZPZPZPZPZPZPZPZPZPZPB G     BDPPPPDA", "                                                               ", "                                                               ", "                                                               ", "                                                               ", "                                                               ", " Q    Q                                                 Q    Q ", " Q    Q                                                 Q    Q " )
                .aisle("AAAAAAAAAAAAAAAAAAAAAAAAAAAAAAAAAAAAAAAAAAAAAAAAAAAAAAAAAAAAAAA", "BCORTVWXYZZZZOYCGHGHGHGHGHGHGHGHGHGHGHGHGHGHGHGCYOZZZZYXWVTROCB", "ADPPPPDB     G BZPZPZPZPZPZPZPZPZPZPZPZPZPZPZPZB G     BDPPPPDA", " I    I                                                 I    I ", " Q    Q                                                 Q    Q ", " Q    Q                                                 Q    Q ", " Q    Q                                                 Q    Q ", " Q    Q                                                 Q    Q ", " QQ  QQ                                                 QQ  QQ ", "  QQQQ                                                   QQQQ  " )
                .aisle("AAAAAAAAAAAAAAAAAAAAAAAAAAAAAAAAAAAAAAAAAAAAAAAAAAAAAAAAAAAAAAA", "BCORTVWXYZZZZOYCHGHGHGHGHGHGHGHGHGHGHGHGHGHGHGHCYOZZZZYXWVTROCB", "ADPPPPDB     G BPZPZPZPZPZPZPZPZPZPZPZPZPZPZPZPB G     BDPPPPDA", " Q    Q                                                 Q    Q ", "                                                               ", "                                                               ", "                                                               ", "                                                               ", "                                                               ", "                                                               " )
                .aisle("AAAAAAAAAAAAAAAAAAAAAAAAAAAAAAAAAAAAAAAAAAAAAAAAAAAAAAAAAAAAAAA", "BCORTVWXYZZZZOYCGHGHGHGHGHGHGHGHGHGHGHGHGHGHGHGCYOZZZZYXWVTROCB", "ADPPPPDB     G BZPZPZPZPZPZPZPZPZPZPZPZPZPZPZPZB G     BDPPPPDA", " Q    Q                                                 Q    Q ", "                                                               ", "                                                               ", "                                                               ", "                                                               ", "                                                               ", "                                                               " )
                .aisle("AAAAAAAAAAAAAAAAAAAAAAAAAAAAAAAAAAAAAAAAAAAAAAAAAAAAAAAAAAAAAAA", "BCORTVWXYZZZZOYCHGHGHGHGHGHGHGHGHGHGHGHGHGHGHGHCYOZZZZYXWVTROCB", "ADPPPPDB     G BPZPZPZPZPZPZPZPZPZPZPZPZPZPZPZPB G     BDPPPPDA", " Q    Q                                                 Q    Q ", "                                                               ", "                                                               ", "                                                               ", "                                                               ", "                                                               ", "                                                               " )
                .aisle("AAAAAAAAAAAAAAAAAAAAAAAAAAAAAAAAAAAAAAAAAAAAAAAAAAAAAAAAAAAAAAA", "BCORTVWXYZZZZOYCGHGHGHGHGHGHGHGHGHGHGHGHGHGHGHGCYOZZZZYXWVTROCB", "ADPPPPDB     G BZPZPZPZPZPZPZPZPZPZPZPZPZPZPZPZB G     BDPPPPDA", " Q    Q                                                 Q    Q ", "                                                               ", "                                                               ", "                                                               ", "                                                               ", "                                                               ", "                                                               " )
                .aisle("AAAAAAAAAAAAAAAAAAAAAAAAAAAAAAAAAAAAAAAAAAAAAAAAAAAAAAAAAAAAAAA", "BCORTVWXYZZZZOYCHGHGHGHGHGHGHGHGHGHGHGHGHGHGHGHCYOZZZZYXWVTROCB", "ADPPPPDB     G BPZPZPZPZPZPZPZPZPZPZPZPZPZPZPZPB G     BDPPPPDA", " Q    Q                                                 Q    Q ", "                                                               ", "                                                               ", "                                                               ", "                                                               ", "                                                               ", "                                                               " )
                .aisle("AAAAAAAAAAAAAAAAAAAAAAAAAAAAAAAAAAAAAAAAAAAAAAAAAAAAAAAAAAAAAAA", "BCORTVWXYZZZZOYCGHGHGHGHGHGHGHGHGHGHGHGHGHGHGHGCYOZZZZYXWVTROCB", "ADPPPPDB     G BZPZPZPZPZPZPZPZPZPZPZPZPZPZPZPZB G     BDPPPPDA", " Q    Q                                                 Q    Q ", "                                                               ", "                                                               ", "                                                               ", "                                                               ", "                                                               ", "                                                               " )
                .aisle("AAAAAAAAAAAAAAAAAAAAAAAAAAAAAAAAAAAAAAAAAAAAAAAAAAAAAAAAAAAAAAA", "BCORTVWXYZZZZOYCHGHGHGHGHGHGHGHGHGHGHGHGHGHGHGHCYOZZZZYXWVTROCB", "ADPPPPDB     G BPZPZPZPZPZPZPZPZPZPZPZPZPZPZPZPB G     BDPPPPDA", " Q    Q                                                 Q    Q ", "                                                               ", "                                                               ", "                                                               ", "                                                               ", "                                                               ", "                                                               " )
                .aisle("AAAAAAAAAAAAAAAAAAAAAAAAAAAAAAAAAAAAAAAAAAAAAAAAAAAAAAAAAAAAAAA", "BCORTVWXYZZZZOYCGHGHGHGHGHGHGHGHGHGHGHGHGHGHGHGCYOZZZZYXWVTROCB", "ADPPPPDB     G BZPZPZPZPZPZPZPZPZPZPZPZPZPZPZPZB G     BDPPPPDA", " Q    Q                                                 Q    Q ", "                                                               ", "                                                               ", "                                                               ", "                                                               ", "                                                               ", "                                                               " )
                .aisle("AAAAAAAAAAAAAAAAAAAAAAAAAAAAAAAAAAAAAAAAAAAAAAAAAAAAAAAAAAAAAAA", "BCORTVWXYZZZZOYCHGHGHGHGHGHGHGHGHGHGHGHGHGHGHGHCYOZZZZYXWVTROCB", "ADPPPPDB     G BPZPZPZPZPZPZPZPZPZPZPZPZPZPZPZPB G     BDPPPPDA", " Q    Q                                                 Q    Q ", "                                                               ", "                                                               ", "                                                               ", "                                                               ", "                                                               ", "                                                               " )
                .aisle("AAAAAAAAAAAAAAAAAAAAAAAAAAAAAAAAAAAAAAAAAAAAAAAAAAAAAAAAAAAAAAA", "BCORTVWXYZZZZOYCGHGHGHGHGHGHGHGHGHGHGHGHGHGHGHGCYOZZZZYXWVTROCB", "ADPPPPDB     G BZPZPZPZPZPZPZPZPZPZPZPZPZPZPZPZB G     BDPPPPDA", " Q    Q                                                 Q    Q ", "                                                               ", "                                                               ", "                                                               ", "                                                               ", "                                                               ", "                                                               " )
                .aisle("AAAAAAAAAAAAAAAAAAAAAAAAAAAAAAAAAAAAAAAAAAAAAAAAAAAAAAAAAAAAAAA", "BCORTVWXYZZZZOYCHGHGHGHGHGHGHGHGHGHGHGHGHGHGHGHCYOZZZZYXWVTROCB", "ADPPPPDB     G BPZPZPZPZPZPZPZPZPZPZPZPZPZPZPZPB G     BDPPPPDA", " Q    Q                                                 Q    Q ", "                                                               ", "                                                               ", "                                                               ", "                                                               ", "                                                               ", "                                                               " )
                .aisle("AAAAAAAAAAAAAAAAAAAAAAAAAAAAAAAAAAAAAAAAAAAAAAAAAAAAAAAAAAAAAAA", "BCORTVWXYZZZZOYCGHGHGHGHGHGHGHGHGHGHGHGHGHGHGHGCYOZZZZYXWVTROCB", "ADPPPPDB     G BZPZPZPZPZPZPZPZPZPZPZPZPZPZPZPZB G     BDPPPPDA", " Q    Q                                                 Q    Q ", "                                                               ", "                                                               ", "                                                               ", "                                                               ", "                                                               ", "                                                               " )
                .aisle("AAAAAAAAAAAAAAAAAAAAAAAAAAAAAAAAAAAAAAAAAAAAAAAAAAAAAAAAAAAAAAA", "BCORTVWXYZZZZOYCCCCCCCCCCCCCCCCCCCCCCCCCCCCCCCCCYOZZZZYXWVTROCB", "ADPPPPDB     G BBBBBBBBBBBBBBBBBBBBBBBBBBBBBBBBB G     BDPPPPDA", " Q    Q                                                 Q    Q ", "                                                               ", "                                                               ", "                                                               ", "                                                               ", "                                                               ", "                                                               " )
                .aisle("AAAAAAAAAAAAAAAAAAAAAAAAAAAAAAAAAAAAAAAAAAAAAAAAAAAAAAAAAAAAAAA", "BCORTVWXYZZZZOYYYYYYYYYYYYYYYYYYYYYYYYYYYYYYYYYYYOZZZZYXWVTROCB", "ADPPPPDB     G                                   G     BDPPPPDA", " Q    Q                                                 Q    Q ", "                                                               ", "                                                               ", "                                                               ", "                                                               ", "                                                               ", "                                                               " )
                .aisle("AAAAAAAAAAAAAAAAAAAAAAAAAAAAAAAAAAAAAAAAAAAAAAAAAAAAAAAAAAAAAAA", "BCORTVWXYZZZZOOOOOOOOOOOOOOOOOOOOOOOOOOOOOOOOOOOOOZZZZYXWVTROCB", "ADPPPPDB     GGGGGGGGGGGGGGGGGGGGGGGGGGGGGGGGGGGGG     BDPPPPDA", " Q    Q      F                                   F      Q    Q ", "                                                               ", "                                                               ", "                                                               ", "                                                               ", "                                                               ", "                                                               " )
                .aisle("AAAAAAAAAAAAAAAAAAAAAAAAAAAAAAAAAAAAAAAAAAAAAAAAAAAAAAAAAAAAAAA", "BCORTVWXYZZZZZZZZZZZZZZZZZZZZZZZZZZZZZZZZZZZZZZZZZZZZZYXWVTROCB", "ADPPPPDB                                               BDPPPPDA", " Q    Q                                                 Q    Q ", "                                                               ", "                                                               ", "                                                               ", "                                                               ", "                                                               ", "                                                               " )
                .aisle("AAAAAAAAAAAAAAAAAAAAAAAAAAAAAAAAAAAAAAAAAAAAAAAAAAAAAAAAAAAAAAA", "BCORTVWXYZZZZZZZZZZZZZZZZZZZZZZZZZZZZZZZZZZZZZZZZZZZZZYXWVTROCB", "ADPPPPDB                                               BDPPPPDA", " Q    Q                                                 Q    Q ", "                                                               ", "                                                               ", "                                                               ", "                                                               ", "                                                               ", "                                                               " )
                .aisle("AAAAAAAAAAAAAAAAAAAAAAAAAAAAAAAAAAAAAAAAAAAAAAAAAAAAAAAAAAAAAAA", "BCORTVWXYZZZZZZZZZZZZZZZZZZZZZZZZZZZZZZZZZZZZZZZZZZZZZYXWVTROCB", "ADPPPPDB                                               BDPPPPDA", " Q    Q                                                 Q    Q ", "                                                               ", "                                                               ", "                                                               ", "                                                               ", "                                                               ", "                                                               " )
                .aisle("AAAAAAAAAAAAAAAAAAAAAAAAAAAAAAAAAAAAAAAAAAAAAAAAAAAAAAAAAAAAAAA", "BCORTVWXYZZZZZZZZZZZZZZZZZZZZZZZZZZZZZZZZZZZZZZZZZZZZZYXWVTROCB", "ADPPPPDB                                               BDPPPPDA", " Q    Q                                                 Q    Q ", "                                                               ", "                                                               ", "                                                               ", "                                                               ", "                                                               ", "                                                               " )
                .aisle("AAAAAAAAAAAAAAAAAAAAAAAAAAAAAAAAAAAAAAAAAAAAAAAAAAAAAAAAAAAAAAA", "BCORTVWXYYYYYYYYYYYYYYYYYYYYYYYYYYYYYYYYYYYYYYYYYYYYYYYXWVTROCB", "ADPPPPDB                                               BDPPPPDA", " Q    Q                                                 Q    Q ", "                                                               ", "                                                               ", "                                                               ", "                                                               ", "                                                               ", "                                                               " )
                .aisle("AAAAAAAAAAAAAAAAAAAAAAAAAAAAAAAAAAAAAAAAAAAAAAAAAAAAAAAAAAAAAAA", "BCORTVWXXXXXXXXXXXXXXXXXXXXXXXXXXXXXXXXXXXXXXXXXXXXXXXXXWVTROCB", "ADPPPPDBBBBBBBBBBBBBBBBBBBBBBBBBBBBBBBBBBBBBBBBBBBBBBBBBDPPPPDA", " Q    Q                                                 Q    Q ", "                                                               ", "                                                               ", "                                                               ", "                                                               ", "                                                               ", "                                                               " )
                .aisle("AAAAAAAAAAAAAAAAAAAAAAAAAAAAAAAAAAAAAAAAAAAAAAAAAAAAAAAAAAAAAAA", "BCORTVWWWWWWWWWWWWWWWWWWWWWWWWWWWWWWWWWWWWWWWWWWWWWWWWWWWVTROCB", "ADPPPPDDDDDDDDDDDDDDDDDDDDDDDDDDDDDDDDDDDDDDDDDDDDDDDDDDDPPPPDA", " Q    QQQQQQQQQQQQQQQQQQQQQQI     IQQQQQQQQQQQQQQQQQQQQQQ    Q ", "      M                     Q     Q                     M      ", "      N                     Q     Q                     N      ", "                            Q     Q                            ", "                            Q     Q                            ", "                            QQ   QQ                            ", "                             QQQQQ                             " )
                .aisle("AAAAAAAAAAAAAAAAAAAAAAAAAAAAAAAAAAAAAAAAAAAAAAAAAAAAAAAAAAAAAAA", "BCORTVVVVVVVVVVVVVVVVVVVVVVVVVVVVVVVVVVVVVVVVVVVVVVVVVVVVVTROCB", "ADPPPPPPPPPPPPPPPPPPPPPPPPPPPPPPPPPPPPPPPPPPPPPPPPPPPPPPPPPPPDA", " Q                                                           Q ", "                                                               ", "                                                               ", "                                                               ", "                                                               ", "                            Q     Q                            ", "                            Q     Q                            " )
                .aisle("AAAAAAAAAAAAAAAAAAAAAAAAAAAAAAAAAAAAAAAAAAAAAAAAAAAAAAAAAAAAAAA", "BCORTTTTTTTTTTTTTTTTTTTTTTTTTTTTTTTTTTTTTTTTTTTTTTTTTTTTTTTROCB", "ADPPPPPPPPPPPPPPPPPPPPPPPPPPPPPPPPPPPPPPPPPPPPPPPPPPPPPPPPPPPDA", " Q                                                           Q ", "                                                               ", "                                                               ", "                                                               ", "                                                               ", "                                                               ", "                            Q     Q                            " )
                .aisle("AAAAAAAAAAAAAAAAAAAAAAAAAAAAAAAAAAAAAAAAAAAAAAAAAAAAAAAAAAAAAAA", "BCORRRRRRRRRRRRRRRRRRRRRRRRRRRRRRRRRRRRRRRRRRRRRRRRRRRRRRRRROCB", "ADPPPPPPPPPPPPPPPPPPPPPPPPPPPPPPPPPPPPPPPPPPPPPPPPPPPPPPPPPPPDA", " Q                                                           Q ", "                                                               ", "                                                               ", "                                                               ", "                                                               ", "                                                               ", "                            Q     Q                            " )
                .aisle("AAAAAAAAAAAAAAAAAAAAAAAAAAAAAAAAAAAAAAAAAAAAAAAAAAAAAAAAAAAAAAA", "BCOOOOOOOOOOOOOOOOOOOOOOOOOOOOOOOOOOOOOOOOOOOOOOOOOOOOOOOOOOOCB", "ADPPPPPPPPPPPPPPPPPPPPPPPPPPPPPPPPPPPPPPPPPPPPPPPPPPPPPPPPPPPDA", " Q                                                           Q ", "                                                               ", "                                                               ", "                                                               ", "                                                               ", "                            Q     Q                            ", "                            Q     Q                            " )
                .aisle("AAAAAAAAAAAAAAAAAAAAAAAAAAAAAAAAAAAAAAAAAAAAAAAAAAAAAAAAAAAAAAA", "BCCCCCCCCCCCCCCCCCCCCCCCCCCCCCCCCCCCCCCCCCCCCCCCCCCCCCCCCCCCCCB", "ADDDDDDDDDDDDDDDDDDDDDDDDDDDDDDDDDDDDDDDDDDDDDDDDDDDDDDDDDDDDDA", " QQQQQQQQQQQQQQQQQQQQQQQQQQQI     IQQQQQQQQQQQQQQQQQQQQQQQQQQQ ", " Q                          Q     Q                          Q ", " M                          Q     Q                          M ", " N                          Q     Q                          N ", "                            Q     Q                            ", "                            QQ   QQ                            ", "                             QQQQQ                             " )
                .aisle("AAAAAAAAAAAAAAAAAAAAAAAAAAAAAAAAAAAAAAAAAAAAAAAAAAAAAAAAAAAAAAA", "BBBBBBBBBBBBBBBBBBBBBBBBBBBBBBBBBBBBBBBBBBBBBBBBBBBBBBBBBBBBBBB", "AAAAAAAAAAAAAAAAAAAAAAAAAAAAAAGEGAAAAAAAAAAAAAAAAAAAAAAAAAAAAAA", "                                                               ", "                                                               ", "                                                               ", "                                                               ", "                                                               ", "                                                               ", "                                                               " )
                .where('E', Predicates.controller(Predicates.blocks(definition.get())))
                .where('A', Predicates.blocks(BotaniaBlocks.livingrockBrick))
                .where('B', Predicates.blocks(GTBlocks.FUSION_GLASS.get()))
                .where('C', Predicates.heatingCoils())
                .where('D', Predicates.blocks(BotaniaBlocks.livingrockBrickMossy))
                .where('F', Predicates.blocks(BotaniaBlocks.manaPylon))
                .where('G', Predicates.blocks(PollutionMagicBlocks.MANA_4.get())
                        .or(Predicates.abilities(PartAbility.OUTPUT_ENERGY).setMaxGlobalLimited(1))
                        .or(Predicates.abilities(PartAbility.OUTPUT_LASER).setMaxGlobalLimited(1))
                        .or(Predicates.abilities(PartAbility.MAINTENANCE).setMaxGlobalLimited(1))
                        .or(Predicates.abilities(PartAbility.INPUT_ENERGY).setMinGlobalLimited(1))
                        .or(Predicates.abilities(PartAbility.IMPORT_FLUIDS).setMinGlobalLimited(1))
                        .or(Predicates.abilities(PartAbility.IMPORT_ITEMS).setMaxGlobalLimited(1))
                        .or(Predicates.abilities(PartAbility.EXPORT_FLUIDS).setMaxGlobalLimited(1)))
                .where('H', Predicates.blocks(PollutionMagicBlocks.MANA_3.get()))
                .where('I', Predicates.blocks(BotaniaBlocks.livingrockBrickChiseled))
                .where('M', Predicates.blocks(BotaniaBlocks.livingrockSlab))
                .where('N', Predicates.blocks(BotaniaBlocks.naturaPylon))
                .where('O', Predicates.blocks(GTBlocks.FUSION_CASING_MK3.get()))
                .where('P', Predicates.blocks(BotaniaBlocks.enchantedSoil))
                .where('Q', Predicates.blocks(BotaniaBlocks.livingrockWall))
                .where('R', Predicates.blocks(GTBlocks.FUSION_CASING_MK3.get()))
                .where('T', Predicates.blocks(PollutionMagicBlocks.MANA_5.get()))
                .where('V', Predicates.blocks(PollutionMagicBlocks.TERRA_2_CASING.get()))
                .where('W', Predicates.blocks(BotaniaBlocks.dragonstoneBlock))
                .where('X', Predicates.blocks(BotaniaBlocks.dreamwoodGlimmering))
                .where('Y', Predicates.blocks(PollutionMagicBlocks.MANA_3.get()))
                .where('Z', Predicates.blocks(PollutionMagicBlocks.MANA_3.get()))
                .where(' ', Predicates.any())
                .build();
    }

    private MultiDanDeLifeOnPatterns() {}
}
