package meowmel.pollution.common.machine.multiblock.node;

import com.gregtechceu.gtceu.api.machine.MultiblockMachineDefinition;
import com.gregtechceu.gtceu.api.machine.multiblock.PartAbility;
import com.gregtechceu.gtceu.api.pattern.BlockPattern;
import com.gregtechceu.gtceu.api.pattern.FactoryBlockPattern;
import com.gregtechceu.gtceu.api.pattern.Predicates;
import com.gregtechceu.gtceu.common.data.GTBlocks;
import com.gregtechceu.gtceu.common.data.GTMaterials;
import meowmel.pollution.common.block.PollutionMagicBlocks;
import meowmel.pollution.common.machine.multiblock.MagicStructureElements;

/** Generated by tools/gen_node_patterns.py - do not edit by hand. */
final class CentralVisTowerPatterns {

    static BlockPattern create(MultiblockMachineDefinition definition) {
        return FactoryBlockPattern.start()
                .aisle("AB           BA", "C             C", "               ", "               ", "               ", "               ", "               ", "               ", "               ", "               ", "       D       ", "       E       ", "               ", "               ", "               ", "               ", "               ", "               ", "               ", "               ", "               ", "               ", "               ", "               ", "               ", "               ", "               ", "               ", "               ", "               ", "               ", "               ", "               ", "               ", "               ", "               ", "               ", "               ", "               ", "               ", "               ", "               ", "               ", "               ", "               ")
                .aisle("BAB         BAB", " C           C ", " C           C ", " C           C ", "               ", "               ", "               ", "               ", "               ", "       A       ", "    DDDFDDD    ", "       G       ", "               ", "               ", "               ", "               ", "               ", "               ", "               ", "               ", "               ", "               ", "               ", "               ", "               ", "               ", "               ", "               ", "               ", "               ", "               ", "               ", "               ", "               ", "               ", "               ", "               ", "               ", "               ", "               ", "               ", "               ", "               ", "               ", "               ")
                .aisle(" BAB       BAB ", "  C         C  ", "  C         C  ", "  C         C  ", "  C         C  ", "  C         C  ", "  C         C  ", "  C         C  ", "  CA       AC  ", "   CAAACAAAC   ", "   DFFFDFFFD   ", "    GGGCGGG    ", "     H H H     ", "               ", "               ", "               ", "               ", "               ", "               ", "               ", "       D       ", "       E       ", "               ", "               ", "               ", "               ", "               ", "               ", "               ", "               ", "               ", "               ", "               ", "               ", "               ", "               ", "               ", "               ", "               ", "               ", "               ", "               ", "               ", "               ", "               ")
                .aisle("  BABBBBBBBAB  ", "   A       A   ", "   A       A   ", "   A       A   ", "   A       A   ", "   A       A   ", "   A       A   ", "   A       A   ", "  ACA     ACA  ", "  CAC     CAC  ", "  DFDDDCDDDFD  ", "   G   G   G   ", "   H   C   H   ", "     H H H     ", "      AAA      ", "      HHH      ", "      AAA      ", "       H       ", "       H       ", "       A       ", "     DDJDD     ", "       G       ", "               ", "               ", "               ", "               ", "               ", "               ", "               ", "               ", "               ", "               ", "               ", "               ", "               ", "               ", "               ", "               ", "               ", "               ", "               ", "               ", "               ", "               ", "               ")
                .aisle("   BACCFCCAB   ", "    A     A    ", "    A     A    ", "    A     A    ", "    A     A    ", "    A     A    ", "    A     A    ", "    A     A    ", "   AA     AA   ", "  ACC     CCA  ", " DFD       DFD ", "  G         G  ", "               ", "    H     H    ", "    HAHHHAH    ", "     HBBBH     ", "     AHHHA     ", "     H   H     ", "     H   H     ", "     AACAA     ", "    DJJDJJD    ", "     GGCGG     ", "               ", "               ", "               ", "               ", "               ", "               ", "               ", "               ", "       D       ", "       E       ", "               ", "               ", "               ", "               ", "               ", "               ", "               ", "               ", "               ", "               ", "               ", "               ", "               ")
                .aisle("   BCBBKBBCB   ", "               ", "               ", "               ", "               ", "               ", "               ", "               ", "               ", "  A         A  ", " DFD       DFD ", "  G         G  ", "  H         H  ", "   H       H   ", "    AH   HA    ", "    HBHHHBH    ", "    AH   HA    ", "    H     H    ", "    H     H    ", "    A  A  A    ", "   DJDDCDDJD   ", "    G  H  G    ", "       H       ", "       H       ", "       H       ", "       H       ", "       H       ", "       H       ", "       H       ", "       A       ", "      DFD      ", "       G       ", "               ", "               ", "               ", "               ", "               ", "               ", "               ", "               ", "               ", "               ", "               ", "               ", "               ")
                .aisle("   BCBKKKBCB   ", "               ", "               ", "               ", "               ", "               ", "               ", "               ", "               ", "  A         A  ", " DFD       DFD ", "  G         G  ", "               ", "               ", "   AH     HA   ", "   HBH   HBH   ", "   AH     HA   ", "               ", "               ", "    A     A    ", "   DJD J DJD   ", "    G     G    ", "               ", "               ", "               ", "               ", "               ", "               ", "               ", "      ACA      ", "     DFDFD     ", "      GHG      ", "       H       ", "       H       ", "       C       ", "               ", "               ", "               ", "               ", "               ", "               ", "               ", "               ", "               ", "               ")
                .aisle("   BFKKKKKFB   ", "               ", "               ", "               ", "               ", "               ", "               ", "               ", "               ", " AC         CA ", "DFDC       CDFD", "EGCG       GCGE", "  HC       CH  ", "   H       H   ", "   AH     HA   ", "   HBH   HBH   ", "   AH     HA   ", "   H       H   ", "   H       H   ", "   ACA   ACA   ", "  DJDCJBJCDJD  ", "  EGCH B HCGE  ", "     H B H     ", "     H B H     ", "     H B H     ", "     H B H     ", "     H B H     ", "     H B H     ", "     H B H     ", "     ACBCA     ", "    DFDBDFD    ", "    EGHBHGE    ", "      HBH      ", "      HBH      ", "      C C      ", "       C       ", "       C       ", "       C       ", "       H       ", "       H       ", "       H       ", "       H       ", "       H       ", "       H       ", "       J       ")
                .aisle("   BCBKKKBCB   ", "               ", "               ", "               ", "               ", "               ", "               ", "               ", "               ", "  A         A  ", " DFD       DFD ", "  G         G  ", "               ", "               ", "   AH     HA   ", "   HBH   HBH   ", "   AH     HA   ", "               ", "               ", "    A     A    ", "   DJD J DJD   ", "    G     G    ", "               ", "               ", "               ", "               ", "               ", "               ", "               ", "      ACA      ", "     DFDFD     ", "      GHG      ", "       H       ", "       H       ", "       C       ", "               ", "               ", "               ", "               ", "               ", "               ", "               ", "               ", "               ", "               ")
                .aisle("   BCBBKBBCB   ", "               ", "               ", "               ", "               ", "               ", "               ", "               ", "               ", "  A         A  ", " DFD       DFD ", "  G         G  ", "  H         H  ", "   H       H   ", "    AH   HA    ", "    HBHHHBH    ", "    AH   HA    ", "    H     H    ", "    H     H    ", "    A  A  A    ", "   DJDDCDDJD   ", "    G  H  G    ", "       H       ", "       H       ", "       H       ", "       H       ", "       H       ", "       H       ", "       H       ", "       A       ", "      DFD      ", "       G       ", "               ", "               ", "               ", "               ", "               ", "               ", "               ", "               ", "               ", "               ", "               ", "               ", "               ")
                .aisle("   BACCFCCAB   ", "    A     A    ", "    A     A    ", "    A     A    ", "    A     A    ", "    A     A    ", "    A     A    ", "    A     A    ", "   AA     AA   ", "  ACC     CCA  ", " DFD       DFD ", "  G         G  ", "               ", "    H     H    ", "    HAHHHAH    ", "     HBBBH     ", "     AHHHA     ", "     H   H     ", "     H   H     ", "     AACAA     ", "    DJJDJJD    ", "     GGCGG     ", "               ", "               ", "               ", "               ", "               ", "               ", "               ", "               ", "       D       ", "       E       ", "               ", "               ", "               ", "               ", "               ", "               ", "               ", "               ", "               ", "               ", "               ", "               ", "               ")
                .aisle("  BABBBBBBBAB  ", "   A       A   ", "   A       A   ", "   A       A   ", "   A       A   ", "   A       A   ", "   A       A   ", "   A       A   ", "  ACA     ACA  ", "  CAC     CAC  ", "  DFDDDCDDDFD  ", "   G   G   G   ", "   H   C   H   ", "     H H H     ", "      AAA      ", "      HSH      ", "      AAA      ", "       H       ", "       H       ", "       A       ", "     DDJDD     ", "       G       ", "               ", "               ", "               ", "               ", "               ", "               ", "               ", "               ", "               ", "               ", "               ", "               ", "               ", "               ", "               ", "               ", "               ", "               ", "               ", "               ", "               ", "               ", "               ")
                .aisle(" BAB       BAB ", "  C         C  ", "  C         C  ", "  C         C  ", "  C         C  ", "  C         C  ", "  C         C  ", "  C         C  ", "  CA       AC  ", "   CAAACAAAC   ", "   DFFFDFFFD   ", "    GGGCGGG    ", "     H H H     ", "               ", "               ", "               ", "               ", "               ", "               ", "               ", "       D       ", "       E       ", "               ", "               ", "               ", "               ", "               ", "               ", "               ", "               ", "               ", "               ", "               ", "               ", "               ", "               ", "               ", "               ", "               ", "               ", "               ", "               ", "               ", "               ", "               ")
                .aisle("BAB         BAB", " C           C ", " C           C ", " C           C ", "               ", "               ", "               ", "               ", "               ", "               ", "    DDDFDDD    ", "       G       ", "               ", "               ", "               ", "               ", "               ", "               ", "               ", "               ", "               ", "               ", "               ", "               ", "               ", "               ", "               ", "               ", "               ", "               ", "               ", "               ", "               ", "               ", "               ", "               ", "               ", "               ", "               ", "               ", "               ", "               ", "               ", "               ", "               ")
                .aisle("AB           BA", "C             C", "               ", "               ", "               ", "               ", "               ", "               ", "               ", "               ", "       D       ", "       E       ", "               ", "               ", "               ", "               ", "               ", "               ", "               ", "               ", "               ", "               ", "               ", "               ", "               ", "               ", "               ", "               ", "               ", "               ", "               ", "               ", "               ", "               ", "               ", "               ", "               ", "               ", "               ", "               ", "               ", "               ", "               ", "               ", "               ")
                .where('S', Predicates.controller(Predicates.blocks(definition.get())))
                .where(' ', Predicates.any())
                .where('A', Predicates.blocks(PollutionMagicBlocks.MANA_BASIC.get()))
                .where('B', frameGroup())
                .where('C', MagicStructureElements.frame(GTMaterials.NaquadahAlloy))
                .where('D', Predicates.blocks(GTBlocks.FUSION_GLASS.get()))
                .where('E', Predicates.blocks(PollutionMagicBlocks.MANA_2.get()))
                .where('F', Predicates.blocks(PollutionMagicBlocks.BEAM_CORE_1.get()))
                .where('G', Predicates.blocks(PollutionMagicBlocks.MANA_1.get()))
                .where('H', Predicates.blocks(PollutionMagicBlocks.LAMINATED_GLASS.get()))
                .where('J', Predicates.blocks(PollutionMagicBlocks.BEAM_CORE_4.get()))
                // 上游: MANA_INPUT_POOL[1,1] -> 本移植版改用 EU + InfusedAura（见机器 javadoc）
                .where('K', Predicates.blocks(PollutionMagicBlocks.MANA_BASIC.get())
                        .or(Predicates.abilities(PartAbility.EXPORT_FLUIDS)
                                .setMinGlobalLimited(3).setMaxGlobalLimited(8))
                        .or(Predicates.abilities(PartAbility.IMPORT_FLUIDS).setExactLimit(1))
                        .or(Predicates.abilities(PartAbility.INPUT_ENERGY).setExactLimit(1))
                        .or(Predicates.abilities(PartAbility.MAINTENANCE).setExactLimit(1)))
                .build();
    }


    private static com.gregtechceu.gtceu.api.pattern.TraceabilityPredicate frameGroup() {
        return MagicStructureElements.frame(GTMaterials.HSSG)
                .or(MagicStructureElements.frame(GTMaterials.NaquadahAlloy))
                .or(MagicStructureElements.frame(GTMaterials.TungstenSteel))
                .or(MagicStructureElements.frame(GTMaterials.StainlessSteel));
    }

    private CentralVisTowerPatterns() {}
}
