package meowmel.pollution.common.machine.multiblock.node;

import com.gregtechceu.gtceu.api.machine.MultiblockMachineDefinition;
import com.gregtechceu.gtceu.api.machine.multiblock.PartAbility;
import com.gregtechceu.gtceu.api.pattern.BlockPattern;
import com.gregtechceu.gtceu.api.pattern.FactoryBlockPattern;
import com.gregtechceu.gtceu.api.pattern.Predicates;
import com.gregtechceu.gtceu.common.data.GTBlocks;
import com.gregtechceu.gtceu.common.data.GTMaterials;
import meowmel.pollution.common.block.PollutionMagicBlocks;
import meowmel.pollution.common.machine.multiblock.MagicStructureElements;

/** Generated by tools/gen_node_patterns.py - do not edit by hand. */
final class NodeBlastFurnacePatterns {

    static BlockPattern create(MultiblockMachineDefinition definition) {
        return FactoryBlockPattern.start()
                .aisle("  ABBBBBBBA  ", "  CBBBBBBBC  ", "   CBBBBBC   ", "             ", "             ", "             ", "             ", "             ", "             ", "             ", "             ", "             ", "             ", "             ", "             ", "             ", "             ", "             ", "             ")
                .aisle(" AADDDBDDDAA ", " CBDDDDDDDBC ", " EC       CE ", "             ", "             ", "  DDDDDDDDD  ", "             ", "             ", "             ", "             ", "             ", "             ", "             ", "             ", "             ", "             ", "             ", "             ", "             ")
                .aisle("AADDDDBDDDDAA", "CBCDDDDDDDCBC", " CC       CC ", "  C       C  ", "  C       C  ", " DC       CD ", "  C       C  ", "  E       E  ", "             ", "             ", "             ", "   DDDDDDD   ", "             ", "             ", "             ", "             ", "             ", "             ", "             ")
                .aisle("BDDDDDBDDDDDB", "BDDCFFFFFCDDB", "C  CGGGGGC  C", "   CGGGGGC   ", "   CGGGGGC   ", " D CHHHHHC D ", "   C     C   ", "   C     C   ", "   C     C   ", "   C     C   ", "   C     C   ", "  DC     CD  ", "   C     C   ", "   E     E   ", "             ", "             ", "    DDDDD    ", "             ", "             ")
                .aisle("BDDDBBBBBDDDB", "BDDFFFFFFFDDB", "B  GIIIIIG  B", "   GIIIIIG   ", "   GIIIIIG   ", " D HFFFFFH D ", "    GGGGG    ", "    GGGGG    ", "    HHHHH    ", "    GGGGG    ", "    GGGGG    ", "  D HHHHH D  ", "    C   C    ", "    C   C    ", "    C   C    ", "    CHHHC    ", "   DCCCCCD   ", "    E   E    ", "             ")
                .aisle("BDDDBDDDBDDDB", "BDDFF   FFDDB", "B  GI   IG  B", "   GI   IG   ", "   GI   IG   ", " D HF   FH D ", "    GIIIG    ", "    GIIIG    ", "    HIIIH    ", "    GIIIG    ", "    GIIIG    ", "  D HFFFH D  ", "     GGG     ", "     GGG     ", "     GGG     ", "    HGGGH    ", "   DCFFFCD   ", "     CCC     ", "     XXX     ")
                .aisle("BBBBBDDDBBBBB", "BDDFF   FFDDB", "B  GI   IG  B", "   GI   IG   ", "   GI   IG   ", " D HF   FH D ", "    GI IG    ", "    GI IG    ", "    HI IH    ", "    GI IG    ", "    GI IG    ", "  D HF FH D  ", "     GIG     ", "     GIG     ", "     GIG     ", "    HGIGH    ", "   DCF FCD   ", "     C C     ", "     XYX     ")
                .aisle("BDDDBDDDBDDDB", "BDDFF   FFDDB", "B  GI   IG  B", "   GI   IG   ", "   GI   IG   ", " D HF   FH D ", "    GIIIG    ", "    GIIIG    ", "    HIIIH    ", "    GIIIG    ", "    GIIIG    ", "  D HFFFH D  ", "     GGG     ", "     GGG     ", "     GGG     ", "    HGGGH    ", "   DCFFFCD   ", "     CCC     ", "     XXX     ")
                .aisle("BDDDBBBBBDDDB", "BDDFFFFFFFDDB", "B  GIIIIIG  B", "   GIIIIIG   ", "   GIIIIIG   ", " D HFFFFFH D ", "    GGGGG    ", "    GGGGG    ", "    HHHHH    ", "    GGGGG    ", "    GGGGG    ", "  D HHHHH D  ", "    C   C    ", "    C   C    ", "    C   C    ", "    CHHHC    ", "   DCCCCCD   ", "    E   E    ", "             ")
                .aisle("BDDDDDBDDDDDB", "BDDCFFFFFCDDB", "C  CGGGGGC  C", "   CGGGGGC   ", "   CGGGGGC   ", " D CHHHHHC D ", "   C     C   ", "   C     C   ", "   C     C   ", "   C     C   ", "   C     C   ", "  DC     CD  ", "   C     C   ", "   E     E   ", "             ", "             ", "    DDDDD    ", "             ", "             ")
                .aisle("AADDDDBDDDDAA", "CBCDDDDDDDCBC", " CC       CC ", "  C       C  ", "  C       C  ", " DC       CD ", "  C       C  ", "  E       E  ", "             ", "             ", "             ", "   DDDDDDD   ", "             ", "             ", "             ", "             ", "             ", "             ", "             ")
                .aisle(" AADDDBDDDAA ", " CBDDDDDDDBC ", " EC       CE ", "             ", "             ", "  DDDDDDDDD  ", "             ", "             ", "             ", "             ", "             ", "             ", "             ", "             ", "             ", "             ", "             ", "             ", "             ")
                .aisle("  ABBBBBBBA  ", "  CBBBSBBBC  ", "   CBBBBBC   ", "             ", "             ", "             ", "             ", "             ", "             ", "             ", "             ", "             ", "             ", "             ", "             ", "             ", "             ", "             ", "             ")
                .where('S', Predicates.controller(Predicates.blocks(definition.get())))
                .where(' ', Predicates.any())
                .where('A', Predicates.blocks(PollutionMagicBlocks.TUNGSTENSTEEL_GEARBOX.get()))
                .where('B', Predicates.blocks(PollutionMagicBlocks.MANA_BASIC.get())
                        .or(Predicates.abilities(PartAbility.INPUT_ENERGY).setMaxGlobalLimited(1))
                        .or(Predicates.abilities(PartAbility.INPUT_LASER).setMaxGlobalLimited(3))
                        .or(Predicates.abilities(PartAbility.MAINTENANCE).setMaxGlobalLimited(1))
                        .setMinGlobalLimited(20))
                .where('C', MagicStructureElements.frame(GTMaterials.HSSG))
                .where('D', Predicates.blocks(PollutionMagicBlocks.VOID_PRISM.get()))
                .where('E', Predicates.blocks(PollutionMagicBlocks.BEAM_CORE_4.get()))
                .where('F', Predicates.blocks(PollutionMagicBlocks.TUNGSTENSTEEL_PIPE.get()))
                .where('G', Predicates.blocks(PollutionMagicBlocks.AAMINATED_GLASS.get()))
                .where('H', Predicates.blocks(PollutionMagicBlocks.BEAM_CORE_0.get()))
                .where('I', Predicates.heatingCoils())
                .where('X', Predicates.blocks(PollutionMagicBlocks.MANA_BASIC.get()))
                .where('Y', Predicates.abilities(PartAbility.MUFFLER).setExactLimit(1))
                .build();
    }

    private NodeBlastFurnacePatterns() {}
}
