package meowmel.pollution.common.machine.multiblock.node;

import com.gregtechceu.gtceu.api.machine.MultiblockMachineDefinition;
import com.gregtechceu.gtceu.api.machine.multiblock.PartAbility;
import com.gregtechceu.gtceu.api.pattern.BlockPattern;
import com.gregtechceu.gtceu.api.pattern.FactoryBlockPattern;
import com.gregtechceu.gtceu.api.pattern.Predicates;
import com.gregtechceu.gtceu.common.data.GTBlocks;
import com.gregtechceu.gtceu.common.data.GTMaterials;
import meowmel.pollution.common.block.PollutionMagicBlocks;
import meowmel.pollution.common.machine.multiblock.MagicStructureElements;

/** Generated by tools/gen_node_patterns.py - do not edit by hand. */
final class NodeFusionReactorPatterns {

    static BlockPattern create(MultiblockMachineDefinition definition) {
        return FactoryBlockPattern.start()
                .aisle("                               ", "                               ", "                               ", "                               ", "                               ", "                               ", "                               ", "                               ", "                               ", "                               ", "                               ", "                               ", "                               ", "                               ", "              ABA              ", "              BDB              ", "              ABA              ", "                               ", "                               ", "                               ", "                               ", "                               ", "                               ", "                               ", "                               ", "                               ", "                               ", "                               ", "                               ", "                               ", "                               ")
                .aisle("                               ", "                               ", "                               ", "                               ", "                               ", "                               ", "                               ", "                               ", "                               ", "                               ", "                               ", "                               ", "                               ", "              ADA              ", "             AADAA             ", "             DDEDD             ", "             AADAA             ", "              ADA              ", "                               ", "                               ", "                               ", "                               ", "                               ", "                               ", "                               ", "                               ", "                               ", "                               ", "                               ", "                               ", "                               ")
                .aisle("                               ", "                               ", "                               ", "                               ", "                               ", "                               ", "                               ", "                               ", "                               ", "                               ", "                               ", "                               ", "              ADA              ", "              ADA              ", "            AABEBAA            ", "            DDEDEDD            ", "            AABEBAA            ", "              ADA              ", "              ADA              ", "                               ", "                               ", "                               ", "                               ", "                               ", "                               ", "                               ", "                               ", "                               ", "                               ", "                               ", "                               ")
                .aisle("                               ", "                               ", "                               ", "                               ", "                               ", "                               ", "                               ", "                               ", "                               ", "                               ", "                               ", "              ADA              ", "              ADA              ", "              BEB              ", "           AAB D BAA           ", "           DDED DEDD           ", "           AAB D BAA           ", "              BEB              ", "              ADA              ", "              ADA              ", "                               ", "                               ", "                               ", "                               ", "                               ", "                               ", "                               ", "                               ", "                               ", "                               ", "                               ")
                .aisle("                               ", "                               ", "                               ", "                               ", "                               ", "                               ", "                               ", "                               ", "                               ", "                               ", "              ADA              ", "              ADA              ", "              BEB              ", "               D               ", "          AAB     BAA          ", "          DDED   DEDD          ", "          AAB     BAA          ", "               D               ", "              BEB              ", "              ADA              ", "              ADA              ", "                               ", "                               ", "                               ", "                               ", "                               ", "                               ", "                               ", "                               ", "                               ", "                               ")
                .aisle("                               ", "                               ", "                               ", "                               ", "                               ", "                               ", "                               ", "                               ", "                               ", "              ADA              ", "              ADA              ", "              BEB              ", "               D               ", "                               ", "         AAB       BAA         ", "         DDED     DEDD         ", "         AAB       BAA         ", "                               ", "               D               ", "              BEB              ", "              ADA              ", "              ADA              ", "                               ", "                               ", "                               ", "                               ", "                               ", "                               ", "                               ", "                               ", "                               ")
                .aisle("                               ", "                               ", "                               ", "                               ", "                               ", "                               ", "                               ", "                               ", "              ADA              ", "              ADA              ", "              BEB              ", "               D               ", "                               ", "                               ", "        AAB         BAA        ", "        DDED       DEDD        ", "        AAB         BAA        ", "                               ", "                               ", "               D               ", "              BEB              ", "              ADA              ", "              ADA              ", "                               ", "                               ", "                               ", "                               ", "                               ", "                               ", "                               ", "                               ")
                .aisle("                               ", "                               ", "                               ", "                               ", "                               ", "                               ", "                               ", "              ADA              ", "              ADA              ", "              BEB              ", "               D               ", "                               ", "                               ", "                               ", "       AAB           BAA       ", "       DDED         DEDD       ", "       AAB           BAA       ", "                               ", "                               ", "                               ", "               D               ", "              BEB              ", "              ADA              ", "              ADA              ", "                               ", "                               ", "                               ", "                               ", "                               ", "                               ", "                               ")
                .aisle("                               ", "                               ", "                               ", "                               ", "                               ", "                               ", "              ADA              ", "              ADA              ", "              BEB              ", "               D               ", "         H           H         ", "                               ", "                               ", "                               ", "      AAB             BAA      ", "      DDED           DEDD      ", "      AAB             BAA      ", "                               ", "                               ", "                               ", "         H           H         ", "               D               ", "              BEB              ", "              ADA              ", "              ADA              ", "                               ", "                               ", "                               ", "                               ", "                               ", "                               ")
                .aisle("                               ", "                               ", "                               ", "                               ", "                               ", "              ADA              ", "              ADA              ", "              BEB              ", "               D               ", "         F           F         ", "        HEG         GEH        ", "         F           F         ", "                               ", "                               ", "     AAB               BAA     ", "     DDED             DEDD     ", "     AAB               BAA     ", "                               ", "                               ", "         F           F         ", "        HEG         GEH        ", "         F           F         ", "               D               ", "              BEB              ", "              ADA              ", "              ADA              ", "                               ", "                               ", "                               ", "                               ", "                               ")
                .aisle("                               ", "                               ", "                               ", "                               ", "              ADA              ", "              ADA              ", "              BEB              ", "               D               ", "                               ", "                               ", "         G           G         ", "                               ", "                               ", "                               ", "    AAB                 BAA    ", "    DDED               DEDD    ", "    AAB                 BAA    ", "                               ", "                               ", "                               ", "         G           G         ", "                               ", "                               ", "               D               ", "              BEB              ", "              ADA              ", "              ADA              ", "                               ", "                               ", "                               ", "                               ")
                .aisle("                               ", "                               ", "                               ", "              ADA              ", "              ADA              ", "              BEB              ", "               D               ", "                               ", "                               ", "                               ", "                               ", "                               ", "                               ", "                               ", "   AAB                   BAA   ", "   DDED                 DEDD   ", "   AAB                   BAA   ", "                               ", "                               ", "                               ", "                               ", "                               ", "                               ", "                               ", "               D               ", "              BEB              ", "              ADA              ", "              ADA              ", "                               ", "                               ", "                               ")
                .aisle("                               ", "                               ", "              ADA              ", "              ADA              ", "              BEB              ", "               D               ", "                               ", "                               ", "                               ", "                               ", "                               ", "                               ", "                               ", "                               ", "  AAB                     BAA  ", "  DDED                   DEDD  ", "  AAB                     BAA  ", "                               ", "                               ", "                               ", "                               ", "                               ", "                               ", "                               ", "                               ", "               D               ", "              BEB              ", "              ADA              ", "              ADA              ", "                               ", "                               ")
                .aisle("                               ", "              ADA              ", "              ADA              ", "              BEB              ", "               D               ", "                               ", "                               ", "                               ", "                               ", "                               ", "                               ", "                               ", "                               ", "                               ", " AAB                       BAA ", " DDED                     DEDD ", " AAB                       BAA ", "                               ", "                               ", "                               ", "                               ", "                               ", "                               ", "                               ", "                               ", "                               ", "               D               ", "              BEB              ", "              ADA              ", "              ADA              ", "                               ")
                .aisle("              ABA              ", "             AADAA             ", "            AABEBAA            ", "           AAB D BAA           ", "          AAB     BAA          ", "         AAB       BAA         ", "        AAB         BAA        ", "       AAB           BAA       ", "      AAB             BAA      ", "     AAB               BAA     ", "    AAB                 BAA    ", "   AAB                   BAA   ", "  AAB                     BAA  ", " AAB                       BAA ", "AAB                         BAA", "BDED                       DEDB", "AAB                         BAA", " AAB                       BAA ", "  AAB                     BAA  ", "   AAB                   BAA   ", "    AAB                 BAA    ", "     AAB               BAA     ", "      AAB             BAA      ", "       AAB           BAA       ", "        AAB         BAA        ", "         AAB       BAA         ", "          AAB     BAA          ", "           AAB D BAA           ", "            AABEBAA            ", "             AADAA             ", "              ABA              ")
                .aisle("              BDB              ", "             DDEDD             ", "            DDEDEDD            ", "           DDED DEDD           ", "          DDED   DEDD          ", "         DDED     DEDD         ", "        DDED       DEDD        ", "       DDED         DEDD       ", "      DDED           DEDD      ", "     DDED             DEDD     ", "    DDED               DEDD    ", "   DDED                 DEDD   ", "  DDED                   DEDD  ", " DDED                     DEDD ", "BDED                       DEDB", "DED                         DED", "BDED                       DEDB", " DDED                     DEDD ", "  DDED                   DEDD  ", "   DDED                 DEDD   ", "    DDED               DEDD    ", "     DDED             DEDD     ", "      DDED           DEDD      ", "       DDED         DEDD       ", "        DDED       DEDD        ", "         DDED     DEDD         ", "          DDED   DEDD          ", "           DDED DEDD           ", "            DDEDEDD            ", "             DDEDD             ", "              BDB              ")
                .aisle("              ABA              ", "             AADAA             ", "            AABEBAA            ", "           AAB D BAA           ", "          AAB     BAA          ", "         AAB       BAA         ", "        AAB         BAA        ", "       AAB           BAA       ", "      AAB             BAA      ", "     AAB               BAA     ", "    AAB                 BAA    ", "   AAB                   BAA   ", "  AAB                     BAA  ", " AAB                       BAA ", "AAB                         BAA", "BDED                       DEDB", "AAB                         BAA", " AAB                       BAA ", "  AAB                     BAA  ", "   AAB                   BAA   ", "    AAB                 BAA    ", "     AAB               BAA     ", "      AAB             BAA      ", "       AAB           BAA       ", "        AAB         BAA        ", "         AAB       BAA         ", "          AAB     BAA          ", "           AAB D BAA           ", "            AABEBAA            ", "             AADAA             ", "              ABA              ")
                .aisle("                               ", "              ADA              ", "              ADA              ", "              BEB              ", "               D               ", "                               ", "                               ", "                               ", "                               ", "                               ", "                               ", "                               ", "                               ", "                               ", " AAB                       BAA ", " DDED                     DEDD ", " AAB                       BAA ", "                               ", "                               ", "                               ", "                               ", "                               ", "                               ", "                               ", "                               ", "                               ", "               D               ", "              BEB              ", "              ADA              ", "              ADA              ", "                               ")
                .aisle("                               ", "                               ", "              ADA              ", "              ADA              ", "              BEB              ", "               D               ", "                               ", "                               ", "                               ", "                               ", "                               ", "                               ", "                               ", "                               ", "  AAB                     BAA  ", "  DDED                   DEDD  ", "  AAB                     BAA  ", "                               ", "                               ", "                               ", "                               ", "                               ", "                               ", "                               ", "                               ", "               D               ", "              BEB              ", "              ADA              ", "              ADA              ", "                               ", "                               ")
                .aisle("                               ", "                               ", "                               ", "              ADA              ", "              ADA              ", "              BEB              ", "               D               ", "                               ", "                               ", "                               ", "                               ", "                               ", "                               ", "                               ", "   AAB                   BAA   ", "   DDED                 DEDD   ", "   AAB                   BAA   ", "                               ", "                               ", "                               ", "                               ", "                               ", "                               ", "                               ", "               D               ", "              BEB              ", "              ADA              ", "              ADA              ", "                               ", "                               ", "                               ")
                .aisle("                               ", "                               ", "                               ", "                               ", "              ADA              ", "              ADA              ", "              BEB              ", "               D               ", "                               ", "                               ", "         G           G         ", "                               ", "                               ", "                               ", "    AAB                 BAA    ", "    DDED               DEDD    ", "    AAB                 BAA    ", "                               ", "                               ", "                               ", "         G           G         ", "                               ", "                               ", "               D               ", "              BEB              ", "              ADA              ", "              ADA              ", "                               ", "                               ", "                               ", "                               ")
                .aisle("                               ", "                               ", "                               ", "                               ", "                               ", "              ADA              ", "              ADA              ", "              BEB              ", "               D               ", "         F           F         ", "        HEG         GEH        ", "         F           F         ", "                               ", "                               ", "     AAB               BAA     ", "     DDED             DEDD     ", "     AAB               BAA     ", "                               ", "                               ", "         F           F         ", "        HEG         GEH        ", "         F           F         ", "               D               ", "              BEB              ", "              ADA              ", "              ADA              ", "                               ", "                               ", "                               ", "                               ", "                               ")
                .aisle("                               ", "                               ", "                               ", "                               ", "                               ", "                               ", "              ADA              ", "              ADA              ", "              BEB              ", "               D               ", "         H           H         ", "                               ", "                               ", "                               ", "      AAB             BAA      ", "      DDED           DEDD      ", "      AAB             BAA      ", "                               ", "                               ", "                               ", "         H           H         ", "               D               ", "              BEB              ", "              ADA              ", "              ADA              ", "                               ", "                               ", "                               ", "                               ", "                               ", "                               ")
                .aisle("                               ", "                               ", "                               ", "                               ", "                               ", "                               ", "                               ", "              ADA              ", "              ADA              ", "              BEB              ", "               D               ", "                               ", "                               ", "                               ", "       AAB           BAA       ", "       DDED         DEDD       ", "       AAB           BAA       ", "                               ", "                               ", "                               ", "               D               ", "              BEB              ", "              ADA              ", "              ADA              ", "                               ", "                               ", "                               ", "                               ", "                               ", "                               ", "                               ")
                .aisle("                               ", "                               ", "                               ", "                               ", "                               ", "                               ", "                               ", "                               ", "              ADA              ", "              ADA              ", "              BEB              ", "               D               ", "                               ", "                               ", "        AAB         BAA        ", "        DDED       DEDD        ", "        AAB         BAA        ", "                               ", "                               ", "               D               ", "              BEB              ", "              ADA              ", "              ADA              ", "                               ", "                               ", "                               ", "                               ", "                               ", "                               ", "                               ", "                               ")
                .aisle("                               ", "                               ", "                               ", "                               ", "                               ", "                               ", "                               ", "                               ", "                               ", "              ADA              ", "              ADA              ", "              BEB              ", "               D               ", "                               ", "         AAB       BAA         ", "         DDED     DEDD         ", "         AAB       BAA         ", "                               ", "               D               ", "              BEB              ", "              ADA              ", "              ADA              ", "                               ", "                               ", "                               ", "                               ", "                               ", "                               ", "                               ", "                               ", "                               ")
                .aisle("                               ", "                               ", "                               ", "                               ", "                               ", "                               ", "                               ", "                               ", "                               ", "                               ", "              ADA              ", "              ADA              ", "              BEB              ", "               D               ", "          AAB     BAA          ", "          DDED   DEDD          ", "          AAB     BAA          ", "               D               ", "              BEB              ", "              ADA              ", "              ADA              ", "                               ", "                               ", "                               ", "                               ", "                               ", "                               ", "                               ", "                               ", "                               ", "                               ")
                .aisle("                               ", "                               ", "                               ", "                               ", "                               ", "                               ", "                               ", "                               ", "                               ", "                               ", "                               ", "              ADA              ", "              ADA              ", "              BEB              ", "           AAB D BAA           ", "           DDED DEDD           ", "           AAB D BAA           ", "              BEB              ", "              ADA              ", "              ADA              ", "                               ", "                               ", "                               ", "                               ", "                               ", "                               ", "                               ", "                               ", "                               ", "                               ", "                               ")
                .aisle("                               ", "                               ", "                               ", "                               ", "                               ", "                               ", "                               ", "                               ", "                               ", "                               ", "                               ", "                               ", "              ADA              ", "              ADA              ", "            AABEBAA            ", "            DDEDEDD            ", "            AABEBAA            ", "              ADA              ", "              ADA              ", "                               ", "                               ", "                               ", "                               ", "                               ", "                               ", "                               ", "                               ", "                               ", "                               ", "                               ", "                               ")
                .aisle("                               ", "                               ", "                               ", "                               ", "                               ", "                               ", "                               ", "                               ", "                               ", "                               ", "                               ", "                               ", "                               ", "              ADA              ", "             AADAA             ", "             DDEDD             ", "             AADAA             ", "              ADA              ", "                               ", "                               ", "                               ", "                               ", "                               ", "                               ", "                               ", "                               ", "                               ", "                               ", "                               ", "                               ", "                               ")
                .aisle("                               ", "                               ", "                               ", "                               ", "                               ", "                               ", "                               ", "                               ", "                               ", "                               ", "                               ", "                               ", "                               ", "                               ", "              ABA              ", "              BSB              ", "              ABA              ", "                               ", "                               ", "                               ", "                               ", "                               ", "                               ", "                               ", "                               ", "                               ", "                               ", "                               ", "                               ", "                               ", "                               ")
                .where('S', Predicates.controller(Predicates.blocks(definition.get())))
                .where(' ', Predicates.any())
                .where('A', Predicates.blocks(GTBlocks.FUSION_GLASS.get()))
                .where('B', Predicates.blocks(PollutionMagicBlocks.BEAM_CORE_1.get()))
                .where('D', Predicates.blocks(PollutionMagicBlocks.VOID_PRISM.get())
                        .or(Predicates.abilities(PartAbility.IMPORT_FLUIDS))
                        .or(Predicates.abilities(PartAbility.INPUT_ENERGY).setMaxGlobalLimited(16))
                        .or(Predicates.abilities(PartAbility.MAINTENANCE).setMaxGlobalLimited(1)))
                .where('E', Predicates.blocks(GTBlocks.SUPERCONDUCTING_COIL.get()))
                .where('F', Predicates.blocks(PollutionMagicBlocks.SPELL_PRISM_VOID.get())
                        .or(Predicates.abilities(PartAbility.IMPORT_FLUIDS).setMaxGlobalLimited(5)))
                .where('G', Predicates.blocks(PollutionMagicBlocks.SPELL_PRISM_VOID.get())
                        .or(Predicates.abilities(PartAbility.EXPORT_FLUIDS).setMaxGlobalLimited(1)))
                .where('H', Predicates.abilities(PartAbility.IMPORT_ITEMS).setExactLimit(1))
                .build();
    }

    private NodeFusionReactorPatterns() {}
}
