package meowmel.pollution.common.machine.multiblock.magic;

import com.gregtechceu.gtceu.api.machine.MultiblockMachineDefinition;
import com.gregtechceu.gtceu.api.machine.multiblock.PartAbility;
import com.gregtechceu.gtceu.api.pattern.BlockPattern;
import com.gregtechceu.gtceu.api.pattern.FactoryBlockPattern;
import com.gregtechceu.gtceu.api.pattern.Predicates;
import com.gregtechceu.gtceu.common.data.GTBlocks;
import com.gregtechceu.gtceu.common.data.GTMaterials;
import meowmel.pollution.common.block.PollutionMagicBlocks;
import meowmel.pollution.common.machine.multiblock.MagicStructureElements;

/** Generated by tools/gen_node_patterns.py - do not edit by hand. */
final class EssenceCollectorPatterns {

    static BlockPattern create(MultiblockMachineDefinition definition) {
        return FactoryBlockPattern.start()
                .aisle("      AAA      ", "      AAA      ", "      CCC      ", "               ", "               ", "               ", "               ", "               ", "      CCC      ", "      AAA      ", "      AAA      ")
                .aisle("   AAAABAAAA   ", "   ACE   ECA   ", "     A   A     ", "     A   A     ", "     A   A     ", "     A   A     ", "     A   A     ", "     A   A     ", "     A   A     ", "   ACE   ECA   ", "   AAAABAAAA   ")
                .aisle("  AAFFABAFFAA  ", "  A         A  ", "               ", "               ", "               ", "               ", "               ", "               ", "               ", "  A         A  ", "  AAFFABAFFAA  ")
                .aisle(" AAFFEABAEFFAA ", " C           C ", "               ", "               ", "               ", "               ", "               ", "               ", "               ", " C           C ", " AAFFEABAEFFAA ")
                .aisle(" AFFEFABAFEFFA ", " E   I   K   E ", " A   I   K   A ", " A   D   D   A ", " A   E   E   A ", " A           A ", " A   E   E   A ", " A   A   A   A ", " A   I   K   A ", " E   I   K   E ", " AFFEFABAFEFFA ")
                .aisle("AAAAAAABAAAAAAA", "A             A", "               ", "               ", "               ", "               ", "               ", "               ", "               ", "A             A", "AAAAAAABAAAAAAA")
                .aisle("ABBBFBBEBBFBBBA", "A   G     L   A", "    G     L    ", "    D     D    ", "    E     E    ", "               ", "    E     E    ", "    A     A    ", "    G     L    ", "A   G     L   A", "ABBBFBBEBBFBBBA")
                .aisle("AAAAAAABAAAAAAA", "A             A", "               ", "               ", "               ", "               ", "               ", "               ", "               ", "A             A", "AAAAAAABAAAAAAA")
                .aisle(" AFFEFABAFEFFA ", " E   H   J   E ", " A   H   J   A ", " A   D   D   A ", " A   E   E   A ", " A           A ", " A   E   E   A ", " A   A   A   A ", " A   H   J   A ", " E   H   J   E ", " AFFEFABAFEFFA ")
                .aisle(" AAFFEABAEFFAA ", " C           C ", "               ", "               ", "               ", "               ", "               ", "               ", "               ", " C           C ", " AAFFEABAEFFAA ")
                .aisle("  AAFFABAFFAA  ", "  A         A  ", "               ", "               ", "               ", "               ", "               ", "               ", "               ", "  A         A  ", "  AAFFABAFFAA  ")
                .aisle("   AAAABAAAA   ", "   ACE   ECA   ", "     A   A     ", "     A   A     ", "     A   A     ", "     A   A     ", "     A   A     ", "     A   A     ", "     A   A     ", "   ACE   ECA   ", "   AAAABAAAA   ")
                .aisle("      AOA      ", "      ASA      ", "      CCC      ", "               ", "               ", "               ", "               ", "               ", "      CCC      ", "      AAA      ", "      AAA      ")
                .where('S', Predicates.controller(Predicates.blocks(definition.get())))
                .where(' ', Predicates.any())
                .where('A', Predicates.blocks(PollutionMagicBlocks.SPELL_PRISM.get())
                        .or(Predicates.abilities(PartAbility.INPUT_ENERGY).setMaxGlobalLimited(2))
                        .or(Predicates.abilities(PartAbility.MAINTENANCE).setMaxGlobalLimited(1))
                        .setMinGlobalLimited(200))
                .where('B', Predicates.heatingCoils())
                .where('C', Predicates.blocks(PollutionMagicBlocks.LAMINATED_GLASS.get()))
                .where('D', Predicates.abilities(PartAbility.EXPORT_FLUIDS).setExactLimit(6))
                .where('E', Predicates.blocks(PollutionMagicBlocks.BEAM_CORE_4.get()))
                .where('F', Predicates.blocks(PollutionMagicBlocks.STAINLESS_STEEL_GEARBOX.get()))
                .where('G', Predicates.blocks(PollutionMagicBlocks.SPELL_PRISM_VOID.get()))
                .where('H', Predicates.blocks(PollutionMagicBlocks.SPELL_PRISM_EARTH.get()))
                .where('I', Predicates.blocks(PollutionMagicBlocks.SPELL_PRISM_WATER.get()))
                .where('J', Predicates.blocks(PollutionMagicBlocks.SPELL_PRISM_HOT.get()))
                .where('K', Predicates.blocks(PollutionMagicBlocks.SPELL_PRISM_AIR.get()))
                .where('L', Predicates.blocks(PollutionMagicBlocks.SPELL_PRISM_ORDER.get()))
                .where('O', Predicates.abilities(PartAbility.IMPORT_ITEMS).setMaxGlobalLimited(2))
                .build();
    }

    private EssenceCollectorPatterns() {}
}
