package meowmel.pollution.common.machine.multiblock.magic;

import com.gregtechceu.gtceu.api.machine.MultiblockMachineDefinition;
import com.gregtechceu.gtceu.api.machine.multiblock.PartAbility;
import com.gregtechceu.gtceu.api.pattern.BlockPattern;
import com.gregtechceu.gtceu.api.pattern.FactoryBlockPattern;
import com.gregtechceu.gtceu.api.pattern.Predicates;
import com.gregtechceu.gtceu.common.data.GTBlocks;
import com.gregtechceu.gtceu.common.data.GTMaterials;
import meowmel.pollution.api.metatileentity.POMultiblockAbility;
import meowmel.pollution.common.block.PollutionMagicBlocks;
import meowmel.pollution.common.machine.multiblock.MagicStructureElements;

/** Generated by tools/gen_node_patterns.py - do not edit by hand. */
final class IndustrialInfusionPatterns {

    static BlockPattern create(MultiblockMachineDefinition definition) {
        return FactoryBlockPattern.start()
                .aisle("             ABA             ", "          BBBABABBB          ", "             ABA             ")
                .aisle("           BBABABB           ", "        BBB C   C BBB        ", "           BBABABB           ")
                .aisle("         BB  ABA  BB         ", "      BBB CBBABABBC BBB      ", "         BB  ABA  BB         ")
                .aisle("       BB           BB       ", "    BBB CBBB D D BBBC BBB    ", "       BB           BB       ")
                .aisle("     BB               BB     ", "   BB CBBB   D D   BBBC BB   ", "     BB               BB     ")
                .aisle("    B  E             E  B    ", "   B BBB     D D     BBB B   ", "    B  E             E  B    ")
                .aisle("    B  E             E  B    ", "  BBCB       D D       BCBB  ", "    B  E             E  B    ")
                .aisle("   B EEE      D      EEE B   ", "  B BB ED    DED    DE BB B  ", "   B EEE      D      EEE B   ")
                .aisle("   B    D     D     D    B   ", " BBCB  DED         DED  BCBB ", "   B    D     D     D    B   ")
                .aisle("  B      D    D    D      B  ", " B BB   DED       DED   BB B ", "  B      D    D    D      B  ")
                .aisle("  B       A   D   A       B  ", "BBCB     DEA  F  AED     BCBB", "  B       A   D   A       B  ")
                .aisle(" B         A     A         B ", "B BB      AEFFFFFEA      BB B", " B         A     A         B ")
                .aisle(" B                         B ", "BCB        FF G FF        BCB", " B                         B ")
                .aisle("AAA          GGG          AAA", "A ADDDDD   F GGG F   DDDDDA A", "AAA          GGG          AAA")
                .aisle("BBB    DDDD  GGG  DDDD    BBB", "B B    E  FFGGGGGFF  E    B B", "BBB    DDDD  GGG  DDDD    BBB")
                .aisle("AAA          GGG          AAA", "A ADDDDD   F GGG F   DDDDDA A", "AAA          GGG          AAA")
                .aisle(" B                         B ", "BCB        FF G FF        BCB", " B                         B ")
                .aisle(" B         A     A         B ", "B BB      AEFFFFFEA      BB B", " B         A     A         B ")
                .aisle("  B       A   D   A       B  ", "BBCB     DEA  F  AED     BCBB", "  B       A   D   A       B  ")
                .aisle("  B      D    D    D      B  ", " B BB   DED       DED   BB B ", "  B      D    D    D      B  ")
                .aisle("   B    D     D     D    B   ", " BBCB  DED         DED  BCBB ", "   B    D     D     D    B   ")
                .aisle("   B EEE      D      EEE B   ", "  B BB ED    DED    DE BB B  ", "   B EEE      D      EEE B   ")
                .aisle("    B  E             E  B    ", "  BBCB       D D       BCBB  ", "    B  E             E  B    ")
                .aisle("    B  E             E  B    ", "   B BBB     D D     BBB B   ", "    B  E             E  B    ")
                .aisle("     BB               BB     ", "   BB CBBB   D D   BBBC BB   ", "     BB               BB     ")
                .aisle("       BB           BB       ", "    BBB CBBB D D BBBC BBB    ", "       BB           BB       ")
                .aisle("         BB  ABA  BB         ", "      BBB CBBABABBC BBB      ", "         BB  ABA  BB         ")
                .aisle("           BBABABB           ", "        BBB C   C BBB        ", "           BBABABB           ")
                .aisle("             ABA             ", "          BBBASABBB          ", "             ABA             ")
                .where('S', Predicates.controller(Predicates.blocks(definition.get())))
                .where(' ', Predicates.any())
                .where('B', Predicates.blocks(PollutionMagicBlocks.SPELL_PRISM_VOID.get())
                        .or(Predicates.abilities(PartAbility.INPUT_ENERGY))
                        .or(Predicates.abilities(PartAbility.IMPORT_ITEMS))
                        .or(Predicates.abilities(PartAbility.EXPORT_ITEMS))
                        .or(Predicates.abilities(PartAbility.IMPORT_FLUIDS))
                        .or(Predicates.abilities(PartAbility.EXPORT_FLUIDS))
                        .or(Predicates.abilities(POMultiblockAbility.VIS_HATCH).setMaxGlobalLimited(1))
                        .or(Predicates.abilities(POMultiblockAbility.INFUSED_FLUID_HATCH).setExactLimit(1))
                        .or(Predicates.abilities(POMultiblockAbility.MANA_INPUT_POOL).setMaxGlobalLimited(1)))
                .where('C', Predicates.blocks(PollutionMagicBlocks.BEAM_CORE_4.get()))
                .where('D', Predicates.blocks(PollutionMagicBlocks.TITANIUM_PIPE.get()))
                .where('E', Predicates.blocks(PollutionMagicBlocks.TITANIUM_GEARBOX.get()))
                .where('F', Predicates.blocks(PollutionMagicBlocks.MAGIC_BATTERY_CASING.get()))
                // 上游: A=CP_COIL_CASING, G=CP_GLASS -> 本移植版: 加热线圈 / 夹层玻璃
                .where('A', Predicates.heatingCoils())
                .where('G', Predicates.blocks(PollutionMagicBlocks.LAMINATED_GLASS.get()))
                .build();
    }

    private IndustrialInfusionPatterns() {}
}
