package meowmel.pollution.common.machine.multiblock.magic;

import com.gregtechceu.gtceu.api.machine.MultiblockMachineDefinition;
import com.gregtechceu.gtceu.api.machine.multiblock.PartAbility;
import com.gregtechceu.gtceu.api.pattern.BlockPattern;
import com.gregtechceu.gtceu.api.pattern.FactoryBlockPattern;
import com.gregtechceu.gtceu.api.pattern.Predicates;
import com.gregtechceu.gtceu.common.data.GTBlocks;
import com.gregtechceu.gtceu.common.data.GTMaterials;
import meowmel.pollution.common.block.PollutionMagicBlocks;
import meowmel.pollution.common.machine.multiblock.MagicStructureElements;

/** Generated by tools/gen_node_patterns.py - do not edit by hand. */
final class MagicBatteryPatterns {

    static BlockPattern create(MultiblockMachineDefinition definition) {
        return FactoryBlockPattern.start()
                .aisle("               ", "               ", "               ", "               ", "               ", "       A       ", "      AAA      ", "     AASAA     ", "      AAA      ", "       A       ", "               ", "               ", "               ", "               ", "               ")
                .aisle("               ", "               ", "               ", "       A       ", "     BBABB     ", "    B  A  B    ", "    B CCC B    ", "   AAACBCAAA   ", "    B CCC B    ", "    B  A  B    ", "     BBABB     ", "       A       ", "               ", "               ", "               ")
                .aisle("               ", "               ", "       A       ", "       A       ", "               ", "               ", "               ", "  AA       AA  ", "               ", "               ", "               ", "       A       ", "       A       ", "               ", "               ")
                .aisle("               ", "       A       ", "       A       ", "               ", "               ", "               ", "               ", " AA         AA ", "               ", "               ", "               ", "               ", "       A       ", "       A       ", "               ")
                .aisle("               ", "     BBABB     ", "               ", "               ", "               ", " B           B ", " B           B ", " A           A ", " B           B ", " B           B ", "               ", "               ", "               ", "     BBABB     ", "               ")
                .aisle("       A       ", "    B  A  B    ", "               ", "               ", " B           B ", "               ", "               ", "AA           AA", "               ", "               ", " B           B ", "               ", "               ", "    B  A  B    ", "       A       ")
                .aisle("      AAA      ", "    B CCC B    ", "               ", "               ", " B           B ", "               ", "AC           CA", "AC           CA", "AC           CA", "               ", " B           B ", "               ", "               ", "    B CCC B    ", "      AAA      ")
                .aisle("     AAAAA     ", "   AAACBCAAA   ", "  AA       AA  ", " AA         AA ", " A           A ", "AA           AA", "AC           CA", "AB           BA", "AC           CA", "AA           AA", " A           A ", " AA         AA ", "  AA       AA  ", "   AAACBCAAA   ", "     AAAAA     ")
                .aisle("      AAA      ", "    B CCC B    ", "               ", "               ", " B           B ", "               ", "AC           CA", "AC           CA", "AC           CA", "               ", " B           B ", "               ", "               ", "    B CCC B    ", "      AAA      ")
                .aisle("       A       ", "    B  A  B    ", "               ", "               ", " B           B ", "               ", "               ", "AA           AA", "               ", "               ", " B           B ", "               ", "               ", "    B  A  B    ", "       A       ")
                .aisle("               ", "     BBABB     ", "               ", "               ", "               ", " B           B ", " B           B ", " A           A ", " B           B ", " B           B ", "               ", "               ", "               ", "     BBABB     ", "               ")
                .aisle("               ", "       A       ", "       A       ", "               ", "               ", "               ", "               ", " AA         AA ", "               ", "               ", "               ", "               ", "       A       ", "       A       ", "               ")
                .aisle("               ", "               ", "       A       ", "       A       ", "               ", "               ", "               ", "  AA       AA  ", "               ", "               ", "               ", "       A       ", "       A       ", "               ", "               ")
                .aisle("               ", "               ", "               ", "       A       ", "     BBABB     ", "    B  A  B    ", "    B CCC B    ", "   AAACBCAAA   ", "    B CCC B    ", "    B  A  B    ", "     BBABB     ", "       A       ", "               ", "               ", "               ")
                .aisle("               ", "               ", "               ", "               ", "               ", "       A       ", "      AAA      ", "     AAAAA     ", "      AAA      ", "       A       ", "               ", "               ", "               ", "               ", "               ")
                .where('S', Predicates.controller(Predicates.blocks(definition.get())))
                .where(' ', Predicates.any())
                .where('A', Predicates.blocks(PollutionMagicBlocks.MAGIC_BATTERY_CASING.get())
                        .or(Predicates.abilities(PartAbility.INPUT_ENERGY).setMaxGlobalLimited(16))
                        .or(Predicates.abilities(PartAbility.OUTPUT_ENERGY).setMaxGlobalLimited(16))
                        .or(Predicates.abilities(PartAbility.MAINTENANCE).setMaxGlobalLimited(1)))
                .where('B', Predicates.blocks(PollutionMagicBlocks.BEAM_CORE_4.get()))
                .where('C', Predicates.heatingCoils())
                .build();
    }

    private MagicBatteryPatterns() {}
}
